Workbook
Name Slicer_Category: #N/A

Sheet DASHBOARD
AJ1: Months | AK1: Sum of Total_Amount
AJ2: Jan | AK2: 25799.15
AJ3: Feb | AK3: 16069.38
AJ4: Mar | AK4: 19899.38
AJ5: Apr | AK5: 27899.16
AJ6: May | AK6: 17039.35
AJ7: Jun | AK7: 19299.45
AJ8: Jul | AK8: 18479.4
AJ9: Aug | AK9: 15759.43
AJ10: Sep | AK10: 12989.51
AJ11: Oct | AK11: 20609.52
AJ12: Nov | AK12: 12309.44
AJ13: Dec | AK13: 23039.3
AJ14: Grand Total | AK14: 229192.47

Sheet Raw Data
A1: Transaction_ID | B1: Date | C1: Customer_ID | D1: Customer_Name | E1: Product_ID | F1: Product_Name | G1: Category | H1: Quantity | I1: Unit_Price | J1: Payment_Method | K1: Region | L1: Customer_Segment | M1: Customer_Since | N1: Total_Amount
A2: TRX0155 | B2: 45393 | C2: CUST023 | D2: Paul Baker | E2: P009 | F2: Monitor | G2: Electronics | H2: 3 | I2: 249.99 | J2: Cash | K2: Central | L2: Basic | M2: 44425 | N2: =I2*H2 -> 749.97
A3: TRX0023 | B3: 45396 | C3: CUST013 | D3: Joseph Jackson | E3: P009 | F3: Monitor | G3: Electronics | H3: 3 | I3: 249.99 | J3: Credit Card | K3: Central | L3: Premium | M3: 44575 | N3: =I3*H3 -> 749.97
A4: TRX0139 | B4: 45399 | C4: CUST021 | D4: Kevin Scott | E4: P005 | F4: Blender | G4: Appliances | H4: 3 | I4: 59.99 | J4: PayPal | K4: South | L4: Standard | M4: 45262 | N4: =I4*H4 -> 179.97
A5: TRX0043 | B5: 45400 | C5: CUST046 | D5: Kathleen Bennett | E5: P005 | F5: Blender | G5: Appliances | H5: 3 | I5: 59.99 | J5: Cash | K5: North | L5: Premium | M5: 45114 | N5: =I5*H5 -> 179.97
A6: TRX0212 | B6: 45400 | C6: CUST003 | D6: Michael Brown | E6: P008 | F6: Bookshelf | G6: Furniture | H6: 5 | I6: 149.99 | J6: Credit Card | K6: North | L6: Premium | M6: 45295 | N6: =I6*H6 -> 749.95
A7: TRX0092 | B7: 45403 | C7: CUST024 | D7: Dorothy Nelson | E7: P005 | F7: Blender | G7: Appliances | H7: 2 | I7: 59.99 | J7: Cash | K7: West | L7: Standard | M7: 44746 | N7: =I7*H7 -> 119.98
A8: TRX0193 | B8: 45403 | C8: CUST024 | D8: Dorothy Nelson | E8: P003 | F8: Headphones | G8: Electronics | H8: 5 | I8: 149.99 | J8: Credit Card | K8: Central | L8: Standard | M8: 44418 | N8: =I8*H8 -> 749.95
A9: TRX0240 | B9: 45403 | C9: CUST017 | D9: Charles Allen | E9: P005 | F9: Blender | G9: Appliances | H9: 3 | I9: 59.99 | J9: Debit Card | K9: South | L9: Basic | M9: 45007 | N9: =I9*H9 -> 179.97
A10: TRX0135 | B10: 45405 | C10: CUST009 | D10: Robert Thomas | E10: P001 | F10: Laptop | G10: Electronics | H10: 3 | I10: 899.99 | J10: PayPal | K10: East | L10: Standard | M10: 45299 | N10: =I10*H10 -> 2699.97
A11: TRX0185 | B11: 45408 | C11: CUST026 | D11: Karen Hill | E11: P005 | F11: Blender | G11: Appliances | H11: 3 | I11: 59.99 | J11: Cash | K11: West | L11: Premium | M11: 45207 | N11: =I11*H11 -> 179.97
A12: TRX0138 | B12: 45408 | C12: CUST022 | D12: Susan Green | E12: P008 | F12: Bookshelf | G12: Furniture | H12: 1 | I12: 149.99 | J12: Credit Card | K12: West | L12: Standard | M12: 45103 | N12: =I12*H12 -> 149.99
A13: TRX0209 | B13: 45408 | C13: CUST046 | D13: Kathleen Bennett | E13: P008 | F13: Bookshelf | G13: Furniture | H13: 5 | I13: 149.99 | J13: Debit Card | K13: North | L13: Basic | M13: 44830 | N13: =I13*H13 -> 749.95
... A251: TRX0064 | B251: 45758 | C251: CUST031 | D251: Steven Turner | E251: P010 | F251: Keyboard | G251: Electronics | H251: 3 | I251: 89.99 | J251: Debit Card | K251: North | L251: Premium | M251: 44878 | N251: =I251*H251 -> 269.97

Sheet Analysis
A1: 📅 Date & Time Functions
A2: Metric | B2: Value
A3: TODAY() | B3: =TODAY() -> 46173
A4: NOW() | B4: =NOW() -> 46173.634
A5: Days Span (DATEDIF) | B5: =DATEDIF(MIN('[1]Raw Data'!B2:B251),MAX('[1]Raw Data'!B2:B251),"D") -> 365
A6: End of This Month | B6: =EOMONTH(TODAY(),0) -> 46173
A7: Timestamp (NOW) | B7: =NOW() -> 46173.634
A9: 🔧 INPUT ASSUMPTIONS (Changing Cells — Blue = User Input)
A10: Parameter | B10: Value
A11: Avg Order Value (Base) | B11: =AVERAGE('Raw Data'!N2:N251) -> 916.76988
A12: Transaction Count (Base) | B12: 250
A14: 📊 SCENARIO COMPARISON TABLE
A15: Scenario | B15: Avg Order Value ($) | C15: Transactions Count | D15: Projected Revenue ($)
A16: 📌 Base Case | B16: =B11 -> 916.76988 | C16: =B12 -> 250 | D16: =B16*C16 -> 229192.47
A17: 🔺 Optimistic (+20%) | B17: =B11*1.2 -> 1100.1239 | C17: =B12*1.1 -> 275 | D17: =B17*C17 -> 302534.06
A18: 🔻 Pessimistic (-15%) | B18: =B11*0.85 -> 779.2544 | C18: =B12*0.9 -> 225 | D18: =B18*C18 -> 175332.24
A19: 💥 Best Case (+35%) | B19: =B11*1.35 -> 1237.6393 | C19: =B12*1.2 -> 300 | D19: =B19*C19 -> 371291.8
A20: ⚠️ Worst Case (-25%) | B20: =B11*0.75 -> 687.57741 | C20: =B12*0.8 -> 200 | D20: =B20*C20 -> 137515.48
A22: GOAL SEEK TABLE
A23: Element | B23: Cell Reference | C23: Value / Target
A24: 📥 Set Cell (Result) | B24: D35 | C24: =B25*C27 -> 229192.5
A25: 📥 By Changing Cell | B25: 916.77 | C25: =B25 -> 916.77
A26: 🎯 To Value (Target) | B26: Manual Entry | C26: 250000
A27: 📌 Transactions Count | B27: Fixed at 250 | C27: 250
A29: 📊 GOAL SEEK RESULT — What Avg Order Value achieves $250,000 revenue?
A30: Metric | B30: Original Value | C30: Goal Seek Result | D30: Change Required
A31: Avg Order Value | B31: =AVERAGE('Raw Data'!N2:N251) -> 916.76988 | C31: =C26/C27 -> 1000 | D31: =C31-B31 -> 83.23012
A32: Projected Revenue | B32: =AVERAGE('Raw Data'!N2:N251)*250 -> 229192.47 | C32: =C26 -> 250000 | D32: =C32-B32 -> 20807.53
A33: Transaction Count | B33: 250 | C33: 250 | D33: 0
A35: Most Frequently Purchased Products
A36: Product Name | B36: Total Qty Sold | C36: Transaction Count | D36: Revenue
A37: Laptop | B37: =SUMIF('Raw Data'!F:F,A37,'Raw Data'!H:H) -> 75 | C37: =COUNTIF('Raw Data'!F:F,A37) -> 24 | D37: =SUMIF('Raw Data'!F:F,A37,'Raw Data'!N:N) -> 67499.25
A38: Smartphone | B38: =SUMIF('Raw Data'!F:F,A38,'Raw Data'!H:H) -> 96 | C38: =COUNTIF('Raw Data'!F:F,A38) -> 31 | D38: =SUMIF('Raw Data'!F:F,A38,'Raw Data'!N:N) -> 67199.04
A39: Headphones | B39: =SUMIF('Raw Data'!F:F,A39,'Raw Data'!H:H) -> 47 | C39: =COUNTIF('Raw Data'!F:F,A39) -> 16 | D39: =SUMIF('Raw Data'!F:F,A39,'Raw Data'!N:N) -> 7049.53
A40: Coffee Maker | B40: =SUMIF('Raw Data'!F:F,A40,'Raw Data'!H:H) -> 39 | C40: =COUNTIF('Raw Data'!F:F,A40) -> 14 | D40: =SUMIF('Raw Data'!F:F,A40,'Raw Data'!N:N) -> 3119.61
A41: Blender | B41: =SUMIF('Raw Data'!F:F,A41,'Raw Data'!H:H) -> 87 | C41: =COUNTIF('Raw Data'!F:F,A41) -> 29 | D41: =SUMIF('Raw Data'!F:F,A41,'Raw Data'!N:N) -> 5219.13
A42: Office Chair | B42: =SUMIF('Raw Data'!F:F,A42,'Raw Data'!H:H) -> 52 | C42: =COUNTIF('Raw Data'!F:F,A42) -> 15 | D42: =SUMIF('Raw Data'!F:F,A42,'Raw Data'!N:N) -> 10399.48
A43: Desk | B43: =SUMIF('Raw Data'!F:F,A43,'Raw Data'!H:H) -> 78 | C43: =COUNTIF('Raw Data'!F:F,A43) -> 26 | D43: =SUMIF('Raw Data'!F:F,A43,'Raw Data'!N:N) -> 23399.22
A44: Bookshelf | B44: =SUMIF('Raw Data'!F:F,A44,'Raw Data'!H:H) -> 102 | C44: =COUNTIF('Raw Data'!F:F,A44) -> 35 | D44: =SUMIF('Raw Data'!F:F,A44,'Raw Data'!N:N) -> 15298.98
A45: Monitor | B45: =SUMIF('Raw Data'!F:F,A45,'Raw Data'!H:H) -> 88 | C45: =COUNTIF('Raw Data'!F:F,A45) -> 26 | D45: =SUMIF('Raw Data'!F:F,A45,'Raw Data'!N:N) -> 21999.12
...

Sheet Visualization
A1: Region | B1: Revenue
A2: Central | B2: 1999.71
A3: East | B3: 2239.67
A4: North | B4: 1119.84
A5: South | B5: 1099.83
A6: West | B6: 1879.69
A7: Grand Total | B7: 8338.74
A20: Product | B20: Revenue
A21: Blender | B21: 5219.13
A22: Bookshelf | B22: 15298.98
A23: Coffee Maker | B23: 3119.61
A24: Desk | B24: 23399.22
A25: Headphones | B25: 7049.53
A26: Keyboard | B26: 8009.11
A27: Laptop | B27: 67499.25
A28: Monitor | B28: 21999.12
A29: Office Chair | B29: 10399.48
A30: Smartphone | B30: 67199.04
A31: Grand Total | B31: 229192.47
A38: Payment method | B38: Count
A39: Cash | B39: 76
A40: Credit Card | B40: 68
A41: Debit Card | B41: 54
A42: PayPal | B42: 52
A43: Grand Total | B43: 250
A58: Row Labels | B58: Revenue
A59: Appliances | B59: 8338.74
A60: Electronics | B60: 171756.05
A61: Furniture | B61: 49097.68
A62: Grand Total | B62: 229192.47
A76: Months | B76: Sum of Total_Amount
A77: Jan | B77: 25799.15
A78: Feb | B78: 16069.38
A79: Mar | B79: 19899.38
A80: Apr | B80: 27899.16
A81: May | B81: 17039.35
A82: Jun | B82: 19299.45
A83: Jul | B83: 18479.4
A84: Aug | B84: 15759.43
A85: Sep | B85: 12989.51
...
